Traceback (most recent call last):
  File "C:\Users\cjcam\miniconda3\envs\ml_venv\lib\site-packages\jupyter_cache\executors\utils.py", line 58, in single_nb_execution
    executenb(
  File "C:\Users\cjcam\miniconda3\envs\ml_venv\lib\site-packages\nbclient\client.py", line 1305, in execute
    return NotebookClient(nb=nb, resources=resources, km=km, **kwargs).execute()
  File "C:\Users\cjcam\miniconda3\envs\ml_venv\lib\site-packages\jupyter_core\utils\__init__.py", line 166, in wrapped
    return loop.run_until_complete(inner)
  File "C:\Users\cjcam\miniconda3\envs\ml_venv\lib\asyncio\base_events.py", line 647, in run_until_complete
    return future.result()
  File "C:\Users\cjcam\miniconda3\envs\ml_venv\lib\site-packages\nbclient\client.py", line 705, in async_execute
    await self.async_execute_cell(
  File "C:\Users\cjcam\miniconda3\envs\ml_venv\lib\site-packages\nbclient\client.py", line 1058, in async_execute_cell
    await self._check_raise_for_error(cell, cell_index, exec_reply)
  File "C:\Users\cjcam\miniconda3\envs\ml_venv\lib\site-packages\nbclient\client.py", line 914, in _check_raise_for_error
    raise CellExecutionError.from_cell_and_msg(cell, exec_reply_content)
nbclient.exceptions.CellExecutionError: An error occurred while executing the following cell:
------------------
# Eliminar la columna de Ã­ndice 1 del DataFrame df
df = df.drop(df.columns[0], axis=1)

# Combinar los DataFrames df_dates y df
df_combined = pd.concat([df_dates, df], axis=1)

df_combined.head()
------------------


[1;31m---------------------------------------------------------------------------[0m
[1;31mNameError[0m                                 Traceback (most recent call last)
Cell [1;32mIn[3], line 5[0m
[0;32m      2[0m df [38;5;241m=[39m df[38;5;241m.[39mdrop(df[38;5;241m.[39mcolumns[[38;5;241m0[39m], axis[38;5;241m=[39m[38;5;241m1[39m)
[0;32m      4[0m [38;5;66;03m# Combinar los DataFrames df_dates y df[39;00m
[1;32m----> 5[0m df_combined [38;5;241m=[39m pd[38;5;241m.[39mconcat([[43mdf_dates[49m, df], axis[38;5;241m=[39m[38;5;241m1[39m)
[0;32m      7[0m df_combined[38;5;241m.[39mhead()

[1;31mNameError[0m: name 'df_dates' is not defined

